ERROR: pip's dependency resolver does not currently take into account all the packages that are installed. This behaviour is the source of the following dependency conflicts.
tensorflow 2.5.0 requires grpcio~=1.34.0, but you have grpcio 1.42.0 which is incompatible.
tensorflow 2.5.0 requires tensorflow-estimator<2.6.0,>=2.5.0rc0, but you have tensorflow-estimator 2.6.0 which is incompatible.
Traceback (most recent call last):
  File "/home/ok_sikha/.local/lib/python3.6/site-packages/transformers/file_utils.py", line 2150, in _get_module
    return importlib.import_module("." + module_name, self.__name__)
  File "/usr/lib64/python3.6/importlib/__init__.py", line 126, in import_module
    return _bootstrap._gcd_import(name[level:], package, level)
  File "<frozen importlib._bootstrap>", line 994, in _gcd_import
  File "<frozen importlib._bootstrap>", line 971, in _find_and_load
  File "<frozen importlib._bootstrap>", line 955, in _find_and_load_unlocked
  File "<frozen importlib._bootstrap>", line 665, in _load_unlocked
  File "<frozen importlib._bootstrap_external>", line 678, in exec_module
  File "<frozen importlib._bootstrap>", line 219, in _call_with_frames_removed
  File "/home/ok_sikha/.local/lib/python3.6/site-packages/transformers/modeling_tf_utils.py", line 637, in <module>
    class TFPreTrainedModel(tf.keras.Model, TFModelUtilsMixin, TFGenerationMixin, PushToHubMixin):
  File "/home/ok_sikha/.local/lib/python3.6/site-packages/tensorflow/python/util/lazy_loader.py", line 62, in __getattr__
    module = self._load()
  File "/home/ok_sikha/.local/lib/python3.6/site-packages/tensorflow/python/util/lazy_loader.py", line 45, in _load
    module = importlib.import_module(self.__name__)
  File "/usr/lib64/python3.6/importlib/__init__.py", line 126, in import_module
    return _bootstrap._gcd_import(name[level:], package, level)
  File "<frozen importlib._bootstrap>", line 994, in _gcd_import
  File "<frozen importlib._bootstrap>", line 971, in _find_and_load
  File "<frozen importlib._bootstrap>", line 941, in _find_and_load_unlocked
  File "<frozen importlib._bootstrap>", line 219, in _call_with_frames_removed
  File "<frozen importlib._bootstrap>", line 994, in _gcd_import
  File "<frozen importlib._bootstrap>", line 971, in _find_and_load
  File "<frozen importlib._bootstrap>", line 941, in _find_and_load_unlocked
  File "<frozen importlib._bootstrap>", line 219, in _call_with_frames_removed
  File "<frozen importlib._bootstrap>", line 994, in _gcd_import
  File "<frozen importlib._bootstrap>", line 971, in _find_and_load
  File "<frozen importlib._bootstrap>", line 941, in _find_and_load_unlocked
  File "<frozen importlib._bootstrap>", line 219, in _call_with_frames_removed
  File "<frozen importlib._bootstrap>", line 994, in _gcd_import
  File "<frozen importlib._bootstrap>", line 971, in _find_and_load
  File "<frozen importlib._bootstrap>", line 955, in _find_and_load_unlocked
  File "<frozen importlib._bootstrap>", line 665, in _load_unlocked
  File "<frozen importlib._bootstrap_external>", line 678, in exec_module
  File "<frozen importlib._bootstrap>", line 219, in _call_with_frames_removed
  File "/home/ok_sikha/.local/lib/python3.6/site-packages/keras/__init__.py", line 25, in <module>
    from keras import models
  File "/home/ok_sikha/.local/lib/python3.6/site-packages/keras/models.py", line 20, in <module>
    from keras import metrics as metrics_module
  File "/home/ok_sikha/.local/lib/python3.6/site-packages/keras/metrics.py", line 27, in <module>
    from keras import activations
  File "/home/ok_sikha/.local/lib/python3.6/site-packages/keras/activations.py", line 20, in <module>
    from keras.layers import advanced_activations
  File "/home/ok_sikha/.local/lib/python3.6/site-packages/keras/layers/__init__.py", line 24, in <module>
    from keras.engine.input_layer import Input
  File "/home/ok_sikha/.local/lib/python3.6/site-packages/keras/engine/input_layer.py", line 21, in <module>
    from keras.engine import base_layer
  File "/home/ok_sikha/.local/lib/python3.6/site-packages/keras/engine/base_layer.py", line 41, in <module>
    from keras.mixed_precision import loss_scale_optimizer
  File "/home/ok_sikha/.local/lib/python3.6/site-packages/keras/mixed_precision/loss_scale_optimizer.py", line 1180, in <module>
    mixed_precision._register_wrapper_optimizer_cls(optimizer_v2.OptimizerV2,
AttributeError: module 'tensorflow.python.training.experimental.mixed_precision' has no attribute '_register_wrapper_optimizer_cls'

The above exception was the direct cause of the following exception:

Traceback (most recent call last):
  File "/home/ok_sikha/.local/lib/python3.6/site-packages/transformers/file_utils.py", line 2150, in _get_module
    return importlib.import_module("." + module_name, self.__name__)
  File "/usr/lib64/python3.6/importlib/__init__.py", line 126, in import_module
    return _bootstrap._gcd_import(name[level:], package, level)
  File "<frozen importlib._bootstrap>", line 994, in _gcd_import
  File "<frozen importlib._bootstrap>", line 971, in _find_and_load
  File "<frozen importlib._bootstrap>", line 941, in _find_and_load_unlocked
  File "<frozen importlib._bootstrap>", line 219, in _call_with_frames_removed
  File "<frozen importlib._bootstrap>", line 994, in _gcd_import
  File "<frozen importlib._bootstrap>", line 971, in _find_and_load
  File "<frozen importlib._bootstrap>", line 955, in _find_and_load_unlocked
  File "<frozen importlib._bootstrap>", line 665, in _load_unlocked
  File "<frozen importlib._bootstrap_external>", line 678, in exec_module
  File "<frozen importlib._bootstrap>", line 219, in _call_with_frames_removed
  File "/home/ok_sikha/.local/lib/python3.6/site-packages/transformers/models/__init__.py", line 19, in <module>
    from . import (
  File "/home/ok_sikha/.local/lib/python3.6/site-packages/transformers/models/layoutlm/__init__.py", line 22, in <module>
    from .configuration_layoutlm import LAYOUTLM_PRETRAINED_CONFIG_ARCHIVE_MAP, LayoutLMConfig
  File "/home/ok_sikha/.local/lib/python3.6/site-packages/transformers/models/layoutlm/configuration_layoutlm.py", line 22, in <module>
    from ...onnx import OnnxConfig, PatchingSpec
  File "/home/ok_sikha/.local/lib/python3.6/site-packages/transformers/onnx/__init__.py", line 17, in <module>
    from .convert import export, validate_model_outputs
  File "/home/ok_sikha/.local/lib/python3.6/site-packages/transformers/onnx/convert.py", line 23, in <module>
    from .. import PreTrainedModel, PreTrainedTokenizer, TensorType, TFPreTrainedModel, is_torch_available
  File "<frozen importlib._bootstrap>", line 1020, in _handle_fromlist
  File "/home/ok_sikha/.local/lib/python3.6/site-packages/transformers/file_utils.py", line 2140, in __getattr__
    module = self._get_module(self._class_to_module[name])
  File "/home/ok_sikha/.local/lib/python3.6/site-packages/transformers/file_utils.py", line 2154, in _get_module
    ) from e
RuntimeError: Failed to import transformers.modeling_tf_utils because of the following error (look up to see its traceback):
module 'tensorflow.python.training.experimental.mixed_precision' has no attribute '_register_wrapper_optimizer_cls'

The above exception was the direct cause of the following exception:

Traceback (most recent call last):
  File "<stdin>", line 3, in <module>
  File "/home/ok_sikha/.local/lib/python3.6/site-packages/flair/__init__.py", line 20, in <module>
    from . import models
  File "/home/ok_sikha/.local/lib/python3.6/site-packages/flair/models/__init__.py", line 1, in <module>
    from .sequence_tagger_model import SequenceTagger, MultiTagger
  File "/home/ok_sikha/.local/lib/python3.6/site-packages/flair/models/sequence_tagger_model.py", line 20, in <module>
    from flair.embeddings import TokenEmbeddings, StackedEmbeddings, Embeddings
  File "/home/ok_sikha/.local/lib/python3.6/site-packages/flair/embeddings/__init__.py", line 6, in <module>
    from .token import TokenEmbeddings
  File "/home/ok_sikha/.local/lib/python3.6/site-packages/flair/embeddings/token.py", line 17, in <module>
    from transformers import AutoTokenizer, AutoConfig, AutoModel, CONFIG_MAPPING, PreTrainedTokenizer, XLNetModel, \
  File "<frozen importlib._bootstrap>", line 1020, in _handle_fromlist
  File "/home/ok_sikha/.local/lib/python3.6/site-packages/transformers/file_utils.py", line 2140, in __getattr__
    module = self._get_module(self._class_to_module[name])
  File "/home/ok_sikha/.local/lib/python3.6/site-packages/transformers/file_utils.py", line 2154, in _get_module
    ) from e
RuntimeError: Failed to import transformers.models.auto because of the following error (look up to see its traceback):
Failed to import transformers.modeling_tf_utils because of the following error (look up to see its traceback):
module 'tensorflow.python.training.experimental.mixed_precision' has no attribute '_register_wrapper_optimizer_cls'
